---
title: 2650. 设计可取消函数
description: LeetCode,2650. 设计可取消函数,设计可取消函数,Design Cancellable Function,解题思路
keywords:
  - LeetCode
  - 2650. 设计可取消函数
  - 设计可取消函数
  - Design Cancellable Function
  - 解题思路
---

# 2650. 设计可取消函数

🔴 <font color=#ff334b>Hard</font>&emsp; 🔗&ensp;[`力扣`](https://leetcode.cn/problems/design-cancellable-function) [`LeetCode`](https://leetcode.com/problems/design-cancellable-function)

## 题目

Sometimes you have a long running task, and you may wish to cancel it before
it completes. To help with this goal, write a function `cancellable` that
accepts a generator object and returns an array of two values: a **cancel
function** and a **promise**.

You may assume the generator function will only yield promises. It is your
function's responsibility to pass the values resolved by the promise back to
the generator. If the promise rejects, your function should throw that error
back to the generator.

If the cancel callback is called before the generator is done, your function
should throw an error back to the generator. That error should be the string
`"Cancelled"` (Not an `Error` object). If the error was caught, the returned
promise should resolve with the next value that was yielded or returned.
Otherwise, the promise should reject with the thrown error. No more code
should be executed.

When the generator is done, the promise your function returned should resolve
the value the generator returned. If, however, the generator throws an error,
the returned promise should reject with the error.

An example of how your code would be used:

> 
> 
> 
> 
> 
> function* tasks() {
> 
>   const val = yield new Promise(resolve => resolve(2 + 2));
> 
>   yield new Promise(resolve => setTimeout(resolve, 100));
> 
>   return val + 1; // calculation shouldn't be done.
> 
> }
> 
> const [cancel, promise] = cancellable(tasks());
> 
> setTimeout(cancel, 50);
> 
> promise.catch(console.log); // logs "Cancelled" at t=50ms
> 
> 

If instead `cancel()` was not called or was called after `t=100ms`, the
promise would have resolved `5`.



**Example 1:**

> Input: 
> 
> generatorFunction = function*() { 
> 
>   return 42; 
> 
> }
> 
> cancelledAt = 100
> 
> Output: {"resolved": 42}
> 
> Explanation:
> 
> const generator = generatorFunction();
> 
> const [cancel, promise] = cancellable(generator);
> 
> setTimeout(cancel, 100);
> 
> promise.then(console.log); // resolves 42 at t=0ms
> 
> 
> 
> The generator immediately yields 42 and finishes. Because of that, the returned promise immediately resolves 42. Note that cancelling a finished generator does nothing.

**Example 2:**

> Input:
> 
> generatorFunction = function*() { 
> 
>   const msg = yield new Promise(res => res("Hello")); 
> 
>   throw `Error: ${msg}`; 
> 
> }
> 
> cancelledAt = null
> 
> Output: {"rejected": "Error: Hello"}
> 
> Explanation:
> 
> A promise is yielded. The function handles this by waiting for it to resolve and then passes the resolved value back to the generator. Then an error is thrown which has the effect of causing the promise to reject with the same thrown error.

**Example 3:**

> Input: 
> 
> generatorFunction = function*() { 
> 
>   yield new Promise(res => setTimeout(res, 200)); 
> 
>   return "Success"; 
> 
> }
> 
> cancelledAt = 100
> 
> Output: {"rejected": "Cancelled"}
> 
> Explanation:
> 
> While the function is waiting for the yielded promise to resolve, cancel() is called. This causes an error message to be sent back to the generator. Since this error is uncaught, the returned promise rejected with this error.

**Example 4:**

> Input:
> 
> generatorFunction = function*() { 
> 
>   let result = 0; 
> 
>   yield new Promise(res => setTimeout(res, 100));
> 
>   result += yield new Promise(res => res(1)); 
> 
>   yield new Promise(res => setTimeout(res, 100)); 
> 
>   result += yield new Promise(res => res(1)); 
> 
>   return result;
> 
> }
> 
> cancelledAt = null
> 
> Output: {"resolved": 2}
> 
> Explanation:
> 
> 4 promises are yielded. Two of those promises have their values added to the result. After 200ms, the generator finishes with a value of 2, and that value is resolved by the returned promise.

**Example 5:**

> Input: 
> 
> generatorFunction = function*() { 
> 
>   let result = 0; 
> 
>   try { 
> 
> > 
> yield new Promise(res => setTimeout(res, 100)); 
> 
> > 
> result += yield new Promise(res => res(1)); 
> 
> > 
> yield new Promise(res => setTimeout(res, 100)); 
> 
> > 
> result += yield new Promise(res => res(1)); 
> 
>   } catch(e) { 
> 
> > 
> return result; 
> 
>   } 
> 
>   return result; 
> 
> }
> 
> cancelledAt = 150
> 
> Output: {"resolved": 1}
> 
> Explanation:
> 
> The first two yielded promises resolve and cause the result to increment. However, at t=150ms, the generator is cancelled. The error sent to the generator is caught and the result is returned and finally resolved by the returned promise.

**Example 6:**

> Input: 
> 
> generatorFunction = function*() { 
> 
>   try { 
> 
> > 
> yield new Promise((resolve, reject) => reject("Promise Rejected")); 
> 
>   } catch(e) { 
> 
> > 
> let a = yield new Promise(resolve => resolve(2));
> 
> > 
> let b = yield new Promise(resolve => resolve(2)); 
> 
> > 
> return a + b; 
> 
>   }; 
> 
> }
> 
> cancelledAt = null
> 
> Output: {"resolved": 4}
> 
> Explanation:
> 
> The first yielded promise immediately rejects. This error is caught. Because the generator hasn't been cancelled, execution continues as usual. It ends up resolving 2 + 2 = 4.



**Constraints:**

  * `cancelledAt == null or 0 <= cancelledAt <= 1000`
  * `generatorFunction` returns a generator object


## 题目大意

有时候你会有一个长时间运行的任务，并且你可能希望在它完成之前取消它。为了实现这个目标，请你编写一个名为 `cancellable`
的函数，它接收一个生成器对象，并返回一个包含两个值的数组：一个 **取消函数** 和一个 **promise** 对象。

你可以假设生成器函数只会生成 promise 对象。你的函数负责将 promise 对象解析的值传回生成器。如果 promise
被拒绝，你的函数应将该错误抛回给生成器。

如果在生成器完成之前调用了取消回调函数，则你的函数应该将错误抛回给生成器。该错误应该是字符串 `"Cancelled"`（而不是一个 `Error`
对象）。如果错误被捕获，则返回的 promise 应该解析为下一个生成或返回的值。否则，promise 应该被拒绝并抛出该错误。不应执行任何其他代码。

当生成器完成时，您的函数返回的 promise 应该解析为生成器返回的值。但是，如果生成器抛出错误，则返回的 promise 应该拒绝并抛出该错误。

下面的示例展示了你的代码会如何被使用：

> 
> 
> 
> 
> 
> function* tasks() {
> 
>   const val = yield new Promise(resolve => resolve(2 + 2));
> 
>   yield new Promise(resolve => setTimeout(resolve, 100));
> 
>   return val + 1; // calculation shouldn't be done.
> 
> }
> 
> const [cancel, promise] = cancellable(tasks());
> 
> setTimeout(cancel, 50);
> 
> promise.catch(console.log); // logs "Cancelled" at t=50ms
> 
> 

相反，如果 `cancel()` 没有被调用或者在 `t=100ms` 之后才被调用，那么 promise 应被解析为 `5` 。



**示例 1：**

> 
> 
> 
> 
> 
> **输入：**
> 
> generatorFunction = function*() { 
> 
>   return 42; 
> 
> }
> 
> cancelledAt = 100
> 
> **输出：**{"resolved": 42}
> 
> **解释：**
> 
> const generator = generatorFunction();
> 
> const [cancel, promise] = cancellable(generator);
> 
> setTimeout(cancel, 100);
> 
> promise.then(console.log); // 在 t=0ms 解析为 42
> 
> 
> 
> 该生成器立即生成 42 并完成。因此，返回的 promise 立即解析为 42。请注意，取消已经完成的生成器没有任何作用。
> 
> 

**示例 2：**

> 
> 
> 
> 
> 
> **输入：**
> 
> generatorFunction = function*() { 
> 
>   const msg = yield new Promise(res => res("Hello")); 
> 
>   throw `Error: ${msg}`; 
> 
> }
> 
> cancelledAt = null
> 
> **输出：**{"rejected": "Error: Hello"}
> 
> **解释：**
> 
> 一个 Promise 被生成。该函数通过等待 promise 解析并将解析后的值传回生成器来处理它。然后抛出一个错误，这会导致 promise 被同样抛出的错误拒绝。
> 
> 

**示例 3：**

> 
> 
> 
> 
> 
> **输入：**
> 
> generatorFunction = function*() { 
> 
>   yield new Promise(res => setTimeout(res, 200)); 
> 
>   return "Success"; 
> 
> }
> 
> cancelledAt = 100
> 
> **输出：**{"rejected": "Cancelled"}
> 
> **解释：**
> 
> 当函数等待被生成的 promise 解析时，cancel() 被调用。这会导致一个错误消息被发送回生成器。由于这个错误没有被捕获，返回的 promise 会因为这个错误而被拒绝。
> 
> 

**示例 4：**

> 
> 
> 
> 
> 
> **输入：**
> 
> generatorFunction = function*() { 
> 
>   let result = 0; 
> 
>   yield new Promise(res => setTimeout(res, 100));
> 
>   result += yield new Promise(res => res(1)); 
> 
>   yield new Promise(res => setTimeout(res, 100)); 
> 
>   result += yield new Promise(res => res(1)); 
> 
>   return result;
> 
> }
> 
> cancelledAt = null
> 
> **输出：**{"resolved": 2}
> 
> **解释：**
> 
> 生成器生成了 4 个 promise 。其中两个 promise 的值被添加到结果中。200ms 后，生成器以值 2 完成，该值被返回的 promise 解析。
> 
> 

**示例 5：**

> 
> 
> 
> 
> 
> **输入：**
> 
> generatorFunction = function*() { 
> 
>   let result = 0; 
> 
>   try { 
> 
> > 
> yield new Promise(res => setTimeout(res, 100)); 
> 
> > 
> result += yield new Promise(res => res(1)); 
> 
> > 
> yield new Promise(res => setTimeout(res, 100)); 
> 
> > 
> result += yield new Promise(res => res(1)); 
> 
>   } catch(e) { 
> 
> > 
> return result; 
> 
>   } 
> 
>   return result; 
> 
> }
> 
> cancelledAt = 150
> 
> **输出：**{"resolved": 1}
> 
> **解释：**
> 
> 前两个生成的 promise 解析并导致结果递增。然而，在 t=150ms 时，生成器被取消了。发送给生成器的错误被捕获，结果被返回并最终由返回的 promise 解析。
> 
> 

**示例 6：**

> 
> 
> 
> 
> 
> **输入：**
> 
> generatorFunction = function*() { 
> 
>   try { 
> 
> > 
> yield new Promise((resolve, reject) => reject("Promise Rejected")); 
> 
>   } catch(e) { 
> 
> > 
> let a = yield new Promise(resolve => resolve(2));
> 
> > 
> let b = yield new Promise(resolve => resolve(2)); 
> 
> > 
> return a + b; 
> 
>   }; 
> 
> }
> 
> cancelledAt = null
> 
> **输出：**{"resolved": 4}
> 
> **解释：**
> 
> 第一个生成的 promise 立即被拒绝。该错误被捕获。因为生成器没有被取消，执行继续像往常一样。最终解析为 2 + 2 = 4。



**提示：**

  * `cancelledAt == null or 0 <= cancelledAt <= 1000`
  * `generatorFunction` 返回一个生成器对象


## 解题思路

#### 复杂度分析

- **时间复杂度**：`O()`，
- **空间复杂度**：`O()`，

## 代码

```javascript

```

## 相关题目

<!-- prettier-ignore -->
| 题号 | 标题 | 题解 | 标签 | 难度 |
| :------: | :------ | :------: | :------ | :------ |
| 2648 | [生成斐波那契数列](https://leetcode.com/problems/generate-fibonacci-sequence) | [[✓]](/problem/2648.md) |  | <font color=#15bd66>Easy</font> |
| 2649 | [嵌套数组生成器](https://leetcode.com/problems/nested-array-generator) | [[✓]](/problem/2649.md) |  | <font color=#ffb800>Medium</font> |